Workbook

Sheet Fluxo de Caixa
F2: =F16/SUM($F16:$O16) -> 0.036503643 | G2: =G16/SUM($F16:$O16) -> 0.13294982 | H2: =H16/SUM($F16:$O16) -> 0.13897895 | I2: =I16/SUM($F16:$O16) -> 0.25335639 | J2: =J16/SUM($F16:$O16) -> 0.067044848 | K2: =K16/SUM($F16:$O16) -> 0.22094563 | L2: =L16/SUM($F16:$O16) -> 0.1049571 | M2: =M16/SUM($F16:$O16) -> 0.045263625 | ... O2: =O16/SUM($F16:$O16) -> 0
C3: 2022 | D3: Recebimentos | E3: Despesas | F3: Transporte | G3: Materiais | H3: Educação | I3: Marketing | J3: Empresa/CRP | K3: Aluguel | L3: Supervisão | M3: Escritório | N3: Reforma | P3: Total
B4: 2022/1 | C4: janeiro | D4: =SUMIF(Entradas!B:B,B4,Entradas!C:C) -> 50 | E4: =SUM(F4:O4) -> 1924.42 | F4: =SUMIFS(Despesas!$C:$C,Despesas!$B:$B,$B4,Despesas!$E:$E,F$3) -> 83.83 | G4: =SUMIFS(Despesas!$C:$C,Despesas!$B:$B,$B4,Despesas!$E:$E,G$3) -> 146.41 | H4: =SUMIFS(Despesas!$C:$C,Despesas!$B:$B,$B4,Despesas!$E:$E,H$3) -> 529.72 | I4: =SUMIFS(Despesas!$C:$C,Despesas!$B:$B,$B4,Despesas!$E:$E,I$3) -> 98.3 | J4: =SUMIFS(Despesas!$C:$C,Despesas!$B:$B,$B4,Despesas!$E:$E,J$3) -> 666.16 | K4: =SUMIFS(Despesas!$C:$C,Despesas!$B:$B,$B4,Despesas!$E:$E,K$3) -> 400 | L4: =SUMIFS(Despesas!$C:$C,Despesas!$B:$B,$B4,Despesas!$E:$E,L$3) -> 0 | M4: =SUMIFS(Despesas!$C:$C,Despesas!$B:$B,$B4,Despesas!$E:$E,M$3) -> 0 | ... O4: =SUMIFS(Despesas!$C:$C,Despesas!$B:$B,$B4,Despesas!$E:$E,O$3) -> 0 | P4: =D4-E4 -> -1874.42
B5: 2022/2 | C5: fevereiro | D5: =SUMIF(Entradas!B:B,B5,Entradas!C:C) -> 350 | E5: =SUM(F5:O5) -> 1557.88 | F5: =SUMIFS(Despesas!$C:$C,Despesas!$B:$B,$B5,Despesas!$E:$E,F$3) -> 22 | G5: =SUMIFS(Despesas!$C:$C,Despesas!$B:$B,$B5,Despesas!$E:$E,G$3) -> 93.01 | H5: =SUMIFS(Despesas!$C:$C,Despesas!$B:$B,$B5,Despesas!$E:$E,H$3) -> 529.72 | I5: =SUMIFS(Despesas!$C:$C,Despesas!$B:$B,$B5,Despesas!$E:$E,I$3) -> 313.15 | J5: =SUMIFS(Despesas!$C:$C,Despesas!$B:$B,$B5,Despesas!$E:$E,J$3) -> 200 | K5: =SUMIFS(Despesas!$C:$C,Despesas!$B:$B,$B5,Despesas!$E:$E,K$3) -> 400 | L5: =SUMIFS(Despesas!$C:$C,Despesas!$B:$B,$B5,Despesas!$E:$E,L$3) -> 0 | M5: =SUMIFS(Despesas!$C:$C,Despesas!$B:$B,$B5,Despesas!$E:$E,M$3) -> 0 | ... O5: =SUMIFS(Despesas!$C:$C,Despesas!$B:$B,$B5,Despesas!$E:$E,O$3) -> 0 | P5: =D5-E5 -> -1207.88
B6: 2022/3 | C6: março | D6: =SUMIF(Entradas!B:B,B6,Entradas!C:C) -> 1745 | E6: =SUM(F6:O6) -> 1952.47 | F6: =SUMIFS(Despesas!$C:$C,Despesas!$B:$B,$B6,Despesas!$E:$E,F$3) -> 179 | G6: =SUMIFS(Despesas!$C:$C,Despesas!$B:$B,$B6,Despesas!$E:$E,G$3) -> 253.97 | H6: =SUMIFS(Despesas!$C:$C,Despesas!$B:$B,$B6,Despesas!$E:$E,H$3) -> 529.72 | I6: =SUMIFS(Despesas!$C:$C,Despesas!$B:$B,$B6,Despesas!$E:$E,I$3) -> 349 | J6: =SUMIFS(Despesas!$C:$C,Despesas!$B:$B,$B6,Despesas!$E:$E,J$3) -> 200 | K6: =SUMIFS(Despesas!$C:$C,Despesas!$B:$B,$B6,Despesas!$E:$E,K$3) -> 400 | L6: =SUMIFS(Despesas!$C:$C,Despesas!$B:$B,$B6,Despesas!$E:$E,L$3) -> 0 | M6: =SUMIFS(Despesas!$C:$C,Despesas!$B:$B,$B6,Despesas!$E:$E,M$3) -> 40.78 | ... O6: =SUMIFS(Despesas!$C:$C,Despesas!$B:$B,$B6,Despesas!$E:$E,O$3) -> 0 | P6: =D6-E6 -> -207.47
B7: 2022/4 | C7: abril | D7: =SUMIF(Entradas!B:B,B7,Entradas!C:C) -> 2450 | E7: =SUM(F7:O7) -> 3588.22 | F7: =SUMIFS(Despesas!$C:$C,Despesas!$B:$B,$B7,Despesas!$E:$E,F$3) -> 119 | G7: =SUMIFS(Despesas!$C:$C,Despesas!$B:$B,$B7,Despesas!$E:$E,G$3) -> 22 | H7: =SUMIFS(Despesas!$C:$C,Despesas!$B:$B,$B7,Despesas!$E:$E,H$3) -> 529.72 | I7: =SUMIFS(Despesas!$C:$C,Despesas!$B:$B,$B7,Despesas!$E:$E,I$3) -> 1689 | J7: =SUMIFS(Despesas!$C:$C,Despesas!$B:$B,$B7,Despesas!$E:$E,J$3) -> 200 | K7: =SUMIFS(Despesas!$C:$C,Despesas!$B:$B,$B7,Despesas!$E:$E,K$3) -> 578.5 | L7: =SUMIFS(Despesas!$C:$C,Despesas!$B:$B,$B7,Despesas!$E:$E,L$3) -> 450 | M7: =SUMIFS(Despesas!$C:$C,Despesas!$B:$B,$B7,Despesas!$E:$E,M$3) -> 0 | ... O7: =SUMIFS(Despesas!$C:$C,Despesas!$B:$B,$B7,Despesas!$E:$E,O$3) -> 0 | P7: =D7-E7 -> -1138.22
B8: 2022/5 | C8: maio | D8: =SUMIF(Entradas!B:B,B8,Entradas!C:C) -> 3350 | E8: =SUM(F8:O8) -> 2881 | F8: =SUMIFS(Despesas!$C:$C,Despesas!$B:$B,$B8,Despesas!$E:$E,F$3) -> 69 | G8: =SUMIFS(Despesas!$C:$C,Despesas!$B:$B,$B8,Despesas!$E:$E,G$3) -> 65 | H8: =SUMIFS(Despesas!$C:$C,Despesas!$B:$B,$B8,Despesas!$E:$E,H$3) -> 529.72 | I8: =SUMIFS(Despesas!$C:$C,Despesas!$B:$B,$B8,Despesas!$E:$E,I$3) -> 1227.3 | J8: =SUMIFS(Despesas!$C:$C,Despesas!$B:$B,$B8,Despesas!$E:$E,J$3) -> 200 | K8: =SUMIFS(Despesas!$C:$C,Despesas!$B:$B,$B8,Despesas!$E:$E,K$3) -> 400 | L8: =SUMIFS(Despesas!$C:$C,Despesas!$B:$B,$B8,Despesas!$E:$E,L$3) -> 300 | M8: =SUMIFS(Despesas!$C:$C,Despesas!$B:$B,$B8,Despesas!$E:$E,M$3) -> 89.98 | ... O8: =SUMIFS(Despesas!$C:$C,Despesas!$B:$B,$B8,Despesas!$E:$E,O$3) -> 0 | P8: =D8-E8 -> 469
B9: 2022/6 | C9: junho | D9: =SUMIF(Entradas!B:B,B9,Entradas!C:C) -> 4250 | E9: =SUM(F9:O9) -> 2634.85 | F9: =SUMIFS(Despesas!$C:$C,Despesas!$B:$B,$B9,Despesas!$E:$E,F$3) -> 149 | G9: =SUMIFS(Despesas!$C:$C,Despesas!$B:$B,$B9,Despesas!$E:$E,G$3) -> 0 | H9: =SUMIFS(Despesas!$C:$C,Despesas!$B:$B,$B9,Despesas!$E:$E,H$3) -> 529.72 | I9: =SUMIFS(Despesas!$C:$C,Despesas!$B:$B,$B9,Despesas!$E:$E,I$3) -> 677.03 | J9: =SUMIFS(Despesas!$C:$C,Despesas!$B:$B,$B9,Despesas!$E:$E,J$3) -> 200 | K9: =SUMIFS(Despesas!$C:$C,Despesas!$B:$B,$B9,Despesas!$E:$E,K$3) -> 437 | L9: =SUMIFS(Despesas!$C:$C,Despesas!$B:$B,$B9,Despesas!$E:$E,L$3) -> 600 | M9: =SUMIFS(Despesas!$C:$C,Despesas!$B:$B,$B9,Despesas!$E:$E,M$3) -> 42.1 | ... O9: =SUMIFS(Despesas!$C:$C,Despesas!$B:$B,$B9,Despesas!$E:$E,O$3) -> 0 | P9: =D9-E9 -> 1615.15
B10: 2022/7 | C10: julho | D10: =SUMIF(Entradas!B:B,B10,Entradas!C:C) -> 4650 | E10: =SUM(F10:O10) -> 3324.51 | F10: =SUMIFS(Despesas!$C:$C,Despesas!$B:$B,$B10,Despesas!$E:$E,F$3) -> 165.54 | G10: =SUMIFS(Despesas!$C:$C,Despesas!$B:$B,$B10,Despesas!$E:$E,G$3) -> 0 | H10: =SUMIFS(Despesas!$C:$C,Despesas!$B:$B,$B10,Despesas!$E:$E,H$3) -> 529.72 | I10: =SUMIFS(Despesas!$C:$C,Despesas!$B:$B,$B10,Despesas!$E:$E,I$3) -> 1538.44 | J10: =SUMIFS(Despesas!$C:$C,Despesas!$B:$B,$B10,Despesas!$E:$E,J$3) -> 200 | K10: =SUMIFS(Despesas!$C:$C,Despesas!$B:$B,$B10,Despesas!$E:$E,K$3) -> 400 | L10: =SUMIFS(Despesas!$C:$C,Despesas!$B:$B,$B10,Despesas!$E:$E,L$3) -> 450 | M10: =SUMIFS(Despesas!$C:$C,Despesas!$B:$B,$B10,Despesas!$E:$E,M$3) -> 40.81 | ... O10: =SUMIFS(Despesas!$C:$C,Despesas!$B:$B,$B10,Despesas!$E:$E,O$3) -> 0 | P10: =D10-E10 -> 1325.49
B11: 2022/8 | C11: agosto | D11: =SUMIF(Entradas!B:B,B11,Entradas!C:C) -> 9700 | E11: =SUM(F11:O11) -> 4024.74 | F11: =SUMIFS(Despesas!$C:$C,Despesas!$B:$B,$B11,Despesas!$E:$E,F$3) -> 155 | G11: =SUMIFS(Despesas!$C:$C,Despesas!$B:$B,$B11,Despesas!$E:$E,G$3) -> 538.43 | H11: =SUMIFS(Despesas!$C:$C,Despesas!$B:$B,$B11,Despesas!$E:$E,H$3) -> 529.72 | I11: =SUMIFS(Despesas!$C:$C,Despesas!$B:$B,$B11,Despesas!$E:$E,I$3) -> 1503.59 | J11: =SUMIFS(Despesas!$C:$C,Despesas!$B:$B,$B11,Despesas!$E:$E,J$3) -> 200 | K11: =SUMIFS(Despesas!$C:$C,Despesas!$B:$B,$B11,Despesas!$E:$E,K$3) -> 458 | L11: =SUMIFS(Despesas!$C:$C,Despesas!$B:$B,$B11,Despesas!$E:$E,L$3) -> 600 | M11: =SUMIFS(Despesas!$C:$C,Despesas!$B:$B,$B11,Despesas!$E:$E,M$3) -> 40 | ... O11: =SUMIFS(Despesas!$C:$C,Despesas!$B:$B,$B11,Despesas!$E:$E,O$3) -> 0 | P11: =D11-E11 -> 5675.26
B12: 2022/9 | C12: setembro | D12: =SUMIF(Entradas!B:B,B12,Entradas!C:C) -> 8000 | E12: =SUM(F12:O12) -> 4929.26 | F12: =SUMIFS(Despesas!$C:$C,Despesas!$B:$B,$B12,Despesas!$E:$E,F$3) -> 173 | G12: =SUMIFS(Despesas!$C:$C,Despesas!$B:$B,$B12,Despesas!$E:$E,G$3) -> 1279.43 | H12: =SUMIFS(Despesas!$C:$C,Despesas!$B:$B,$B12,Despesas!$E:$E,H$3) -> 529.72 | I12: =SUMIFS(Despesas!$C:$C,Despesas!$B:$B,$B12,Despesas!$E:$E,I$3) -> 1199.07 | J12: =SUMIFS(Despesas!$C:$C,Despesas!$B:$B,$B12,Despesas!$E:$E,J$3) -> 200 | K12: =SUMIFS(Despesas!$C:$C,Despesas!$B:$B,$B12,Despesas!$E:$E,K$3) -> 612 | L12: =SUMIFS(Despesas!$C:$C,Despesas!$B:$B,$B12,Despesas!$E:$E,L$3) -> 600 | M12: =SUMIFS(Despesas!$C:$C,Despesas!$B:$B,$B12,Despesas!$E:$E,M$3) -> 336.04 | ... O12: =SUMIFS(Despesas!$C:$C,Despesas!$B:$B,$B12,Despesas!$E:$E,O$3) -> 0 | P12: =D12-E12 -> 3070.74
B13: 2022/10 | C13: outubro | D13: =SUMIF(Entradas!B:B,B13,Entradas!C:C) -> 12689.95 | E13: =SUM(F13:O13) -> 5634.61 | F13: =SUMIFS(Despesas!$C:$C,Despesas!$B:$B,$B13,Despesas!$E:$E,F$3) -> 234.23 | G13: =SUMIFS(Despesas!$C:$C,Despesas!$B:$B,$B13,Despesas!$E:$E,G$3) -> 1337.06 | H13: =SUMIFS(Despesas!$C:$C,Despesas!$B:$B,$B13,Despesas!$E:$E,H$3) -> 529.72 | I13: =SUMIFS(Despesas!$C:$C,Despesas!$B:$B,$B13,Despesas!$E:$E,I$3) -> 1627.56 | J13: =SUMIFS(Despesas!$C:$C,Despesas!$B:$B,$B13,Despesas!$E:$E,J$3) -> 200 | K13: =SUMIFS(Despesas!$C:$C,Despesas!$B:$B,$B13,Despesas!$E:$E,K$3) -> 920 | L13: =SUMIFS(Despesas!$C:$C,Despesas!$B:$B,$B13,Despesas!$E:$E,L$3) -> 750 | M13: =SUMIFS(Despesas!$C:$C,Despesas!$B:$B,$B13,Despesas!$E:$E,M$3) -> 36.04 | ... O13: =SUMIFS(Despesas!$C:$C,Despesas!$B:$B,$B13,Despesas!$E:$E,O$3) -> 0 | P13: =D13-E13 -> 7055.34
B14: 2022/11 | C14: novembro | D14: =SUMIF(Entradas!B:B,B14,Entradas!C:C) -> 12995 | E14: =SUM(F14:O14) -> 4350.35 | F14: =SUMIFS(Despesas!$C:$C,Despesas!$B:$B,$B14,Despesas!$E:$E,F$3) -> 240.82 | G14: =SUMIFS(Despesas!$C:$C,Despesas!$B:$B,$B14,Despesas!$E:$E,G$3) -> 1278.08 | H14: =SUMIFS(Despesas!$C:$C,Despesas!$B:$B,$B14,Despesas!$E:$E,H$3) -> 529.72 | I14: =SUMIFS(Despesas!$C:$C,Despesas!$B:$B,$B14,Despesas!$E:$E,I$3) -> 577.48 | J14: =SUMIFS(Despesas!$C:$C,Despesas!$B:$B,$B14,Despesas!$E:$E,J$3) -> 200 | K14: =SUMIFS(Despesas!$C:$C,Despesas!$B:$B,$B14,Despesas!$E:$E,K$3) -> 889 | L14: =SUMIFS(Despesas!$C:$C,Despesas!$B:$B,$B14,Despesas!$E:$E,L$3) -> 600 | M14: =SUMIFS(Despesas!$C:$C,Despesas!$B:$B,$B14,Despesas!$E:$E,M$3) -> 35.25 | ... O14: =SUMIFS(Despesas!$C:$C,Despesas!$B:$B,$B14,Despesas!$E:$E,O$3) -> 0 | P14: =D14-E14 -> 8644.65
B15: 2022/12 | C15: dezembro | D15: =SUMIF(Entradas!B:B,B15,Entradas!C:C) -> 8000 | E15: =SUM(F15:O15) -> 8930.66 | F15: =SUMIFS(Despesas!$C:$C,Despesas!$B:$B,$B15,Despesas!$E:$E,F$3) -> 79 | G15: =SUMIFS(Despesas!$C:$C,Despesas!$B:$B,$B15,Despesas!$E:$E,G$3) -> 1066.8 | H15: =SUMIFS(Despesas!$C:$C,Despesas!$B:$B,$B15,Despesas!$E:$E,H$3) -> 529 | I15: =SUMIFS(Despesas!$C:$C,Despesas!$B:$B,$B15,Despesas!$E:$E,I$3) -> 786.82 | J15: =SUMIFS(Despesas!$C:$C,Despesas!$B:$B,$B15,Despesas!$E:$E,J$3) -> 400 | K15: =SUMIFS(Despesas!$C:$C,Despesas!$B:$B,$B15,Despesas!$E:$E,K$3) -> 4210 | L15: =SUMIFS(Despesas!$C:$C,Despesas!$B:$B,$B15,Despesas!$E:$E,L$3) -> 450 | M15: =SUMIFS(Despesas!$C:$C,Despesas!$B:$B,$B15,Despesas!$E:$E,M$3) -> 1409.04 | ... O15: =SUMIFS(Despesas!$C:$C,Despesas!$B:$B,$B15,Despesas!$E:$E,O$3) -> 0 | P15: =D15-E15 -> -930.66
C16: Fluxo | D16: =SUM(D4:D15) -> 68229.95 | E16: =SUM(E4:E15) -> 45732.97 | F16: =SUM(F4:F15) -> 1669.42 | G16: =SUM(G4:G15) -> 6080.19 | H16: =SUM(H4:H15) -> 6355.92 | I16: =SUM(I4:I15) -> 11586.74 | J16: =SUM(J4:J15) -> 3066.16 | K16: =SUM(K4:K15) -> 10104.5 | ... P16: =SUM(P4:P15) -> 22496.98
F18: =F32/SUM($F32:$O32) -> 0.008834294 | G18: =G32/SUM($F32:$O32) -> 0.0087708372 | H18: =H32/SUM($F32:$O32) -> 0.044721373 | I18: =I32/SUM($F32:$O32) -> 0.040524978 | J18: =J32/SUM($F32:$O32) -> 0.029775956 | K18: =K32/SUM($F32:$O32) -> 0.38968688 | L18: =L32/SUM($F32:$O32) -> 0.081130413 | M18: =M32/SUM($F32:$O32) -> 0.039570349 | ... O18: =O32/SUM($F32:$O32) -> 0
C19: 2023 | D19: =D3 -> Recebimentos | E19: =E3 -> Despesas | F19: =F3 -> Transporte | G19: =G3 -> Materiais | H19: =H3 -> Educação | I19: =I3 -> Marketing | J19: =J3 -> Empresa/CRP | K19: =K3 -> Aluguel | ... O19: =O3 -> 0 | P19: Total
B20: 2023/1 | C20: janeiro | D20: =SUMIF(Entradas!B:B,B20,Entradas!C:C) -> 10650 | E20: =SUM(F20:O20) -> 14217.29 | F20: =SUMIFS(Despesas!$C:$C,Despesas!$B:$B,$B20,Despesas!$E:$E,F$3) -> 113 | G20: =SUMIFS(Despesas!$C:$C,Despesas!$B:$B,$B20,Despesas!$E:$E,G$3) -> 37 | H20: =SUMIFS(Despesas!$C:$C,Despesas!$B:$B,$B20,Despesas!$E:$E,H$3) -> 529.72 | I20: =SUMIFS(Despesas!$C:$C,Despesas!$B:$B,$B20,Despesas!$E:$E,I$3) -> 716.28 | J20: =SUMIFS(Despesas!$C:$C,Despesas!$B:$B,$B20,Despesas!$E:$E,J$3) -> 738.46 | K20: =SUMIFS(Despesas!$C:$C,Despesas!$B:$B,$B20,Despesas!$E:$E,K$3) -> 3841.4 | L20: =SUMIFS(Despesas!$C:$C,Despesas!$B:$B,$B20,Despesas!$E:$E,L$3) -> 600 | M20: =SUMIFS(Despesas!$C:$C,Despesas!$B:$B,$B20,Despesas!$E:$E,M$3) -> 35.25 | ... O20: =SUMIFS(Despesas!$C:$C,Despesas!$B:$B,$B20,Despesas!$E:$E,O$3) -> 0 | P20: =D20-E20 -> -3567.29
B21: 2023/2 | C21: fevereiro | D21: =SUMIF(Entradas!B:B,B21,Entradas!C:C) -> 12725 | E21: =SUM(F21:O21) -> 20683.86 | F21: =SUMIFS(Despesas!$C:$C,Despesas!$B:$B,$B21,Despesas!$E:$E,F$3) -> 195 | G21: =SUMIFS(Despesas!$C:$C,Despesas!$B:$B,$B21,Despesas!$E:$E,G$3) -> 342 | H21: =SUMIFS(Despesas!$C:$C,Despesas!$B:$B,$B21,Despesas!$E:$E,H$3) -> 529.72 | I21: =SUMIFS(Despesas!$C:$C,Despesas!$B:$B,$B21,Despesas!$E:$E,I$3) -> 306 | J21: =SUMIFS(Despesas!$C:$C,Despesas!$B:$B,$B21,Despesas!$E:$E,J$3) -> 215 | K21: =SUMIFS(Despesas!$C:$C,Despesas!$B:$B,$B21,Despesas!$E:$E,K$3) -> 3946.34 | L21: =SUMIFS(Despesas!$C:$C,Despesas!$B:$B,$B21,Despesas!$E:$E,L$3) -> 750 | M21: =SUMIFS(Despesas!$C:$C,Despesas!$B:$B,$B21,Despesas!$E:$E,M$3) -> 21 | ... O21: =SUMIFS(Despesas!$C:$C,Despesas!$B:$B,$B21,Despesas!$E:$E,O$3) -> 0 | P21: =D21-E21 -> -7958.86
B22: 2023/3 | C22: março | D22: =SUMIF(Entradas!B:B,B22,Entradas!C:C) -> 12809.36 | E22: =SUM(F22:O22) -> 13173.61 | F22: =SUMIFS(Despesas!$C:$C,Despesas!$B:$B,$B22,Despesas!$E:$E,F$3) -> 60 | G22: =SUMIFS(Despesas!$C:$C,Despesas!$B:$B,$B22,Despesas!$E:$E,G$3) -> 0 | H22: =SUMIFS(Despesas!$C:$C,Despesas!$B:$B,$B22,Despesas!$E:$E,H$3) -> 794.58 | I22: =SUMIFS(Despesas!$C:$C,Despesas!$B:$B,$B22,Despesas!$E:$E,I$3) -> 271 | J22: =SUMIFS(Despesas!$C:$C,Despesas!$B:$B,$B22,Despesas!$E:$E,J$3) -> 215 | K22: =SUMIFS(Despesas!$C:$C,Despesas!$B:$B,$B22,Despesas!$E:$E,K$3) -> 3771.74 | L22: =SUMIFS(Despesas!$C:$C,Despesas!$B:$B,$B22,Despesas!$E:$E,L$3) -> 600 | M22: =SUMIFS(Despesas!$C:$C,Despesas!$B:$B,$B22,Despesas!$E:$E,M$3) -> 96.4 | ... O22: =SUMIFS(Despesas!$C:$C,Despesas!$B:$B,$B22,Despesas!$E:$E,O$3) -> 0 | P22: =D22-E22 -> -364.25
B23: 2023/4 | C23: abril | D23: =SUMIF(Entradas!B:B,B23,Entradas!C:C) -> 11101.25 | E23: =SUM(F23:O23) -> 12244.3 | F23: 60 | G23: =SUMIFS(Despesas!$C:$C,Despesas!$B:$B,$B23,Despesas!$E:$E,G$3) -> 0 | H23: =SUMIFS(Despesas!$C:$C,Despesas!$B:$B,$B23,Despesas!$E:$E,H$3) -> 629.72 | I23: =SUMIFS(Despesas!$C:$C,Despesas!$B:$B,$B23,Despesas!$E:$E,I$3) -> 249 | J23: =SUMIFS(Despesas!$C:$C,Despesas!$B:$B,$B23,Despesas!$E:$E,J$3) -> 215 | K23: =SUMIFS(Despesas!$C:$C,Despesas!$B:$B,$B23,Despesas!$E:$E,K$3) -> 5514.99 | L23: =SUMIFS(Despesas!$C:$C,Despesas!$B:$B,$B23,Despesas!$E:$E,L$3) -> 950 | M23: =SUMIFS(Despesas!$C:$C,Despesas!$B:$B,$B23,Despesas!$E:$E,M$3) -> 339.3 | N23: =SUMIFS(Despesas!$C:$C,Despesas!$B:$B,$B23,Despesas!$E:$E,N$3) -> 4286.29 | O23: =SUMIFS(Despesas!$C:$C,Despesas!$B:$B,$B23,Despesas!$E:$E,O$3) -> 0 | P23: =D23-E23 -> -1143.05
B24: 2023/5 | C24: maio | D24: =SUMIF(Entradas!B:B,B24,Entradas!C:C) -> 8906.25 | E24: =SUM(F24:O24) -> 9868.9 | F24: =SUMIFS(Despesas!$C:$C,Despesas!$B:$B,$B24,Despesas!$E:$E,F$3) -> 60 | G24: =SUMIFS(Despesas!$C:$C,Despesas!$B:$B,$B24,Despesas!$E:$E,G$3) -> 0 | H24: =SUMIFS(Despesas!$C:$C,Despesas!$B:$B,$B24,Despesas!$E:$E,H$3) -> 529.72 | I24: =SUMIFS(Despesas!$C:$C,Despesas!$B:$B,$B24,Despesas!$E:$E,I$3) -> 249 | J24: =SUMIFS(Despesas!$C:$C,Despesas!$B:$B,$B24,Despesas!$E:$E,J$3) -> 215 | K24: =SUMIFS(Despesas!$C:$C,Despesas!$B:$B,$B24,Despesas!$E:$E,K$3) -> 3642.96 | L24: =SUMIFS(Despesas!$C:$C,Despesas!$B:$B,$B24,Despesas!$E:$E,L$3) -> 600 | M24: =SUMIFS(Despesas!$C:$C,Despesas!$B:$B,$B24,Despesas!$E:$E,M$3) -> 370.95 | ... O24: =SUMIFS(Despesas!$C:$C,Despesas!$B:$B,$B24,Despesas!$E:$E,O$3) -> 0 | P24: =D24-E24 -> -962.65
B25: 2023/6 | C25: junho | D25: =SUMIF(Entradas!B:B,B25,Entradas!C:C) -> 13011.25 | E25: =SUM(F25:O25) -> 8560.26 | F25: =SUMIFS(Despesas!$C:$C,Despesas!$B:$B,$B25,Despesas!$E:$E,F$3) -> 70 | G25: =SUMIFS(Despesas!$C:$C,Despesas!$B:$B,$B25,Despesas!$E:$E,G$3) -> 475.36 | H25: =SUMIFS(Despesas!$C:$C,Despesas!$B:$B,$B25,Despesas!$E:$E,H$3) -> 529.72 | I25: =SUMIFS(Despesas!$C:$C,Despesas!$B:$B,$B25,Despesas!$E:$E,I$3) -> 1048 | J25: =SUMIFS(Despesas!$C:$C,Despesas!$B:$B,$B25,Despesas!$E:$E,J$3) -> 215 | K25: =SUMIFS(Despesas!$C:$C,Despesas!$B:$B,$B25,Despesas!$E:$E,K$3) -> 3642.96 | L25: =SUMIFS(Despesas!$C:$C,Despesas!$B:$B,$B25,Despesas!$E:$E,L$3) -> 810 | M25: =SUMIFS(Despesas!$C:$C,Despesas!$B:$B,$B25,Despesas!$E:$E,M$3) -> 115.7 | ... O25: =SUMIFS(Despesas!$C:$C,Despesas!$B:$B,$B25,Despesas!$E:$E,O$3) -> 0 | P25: =D25-E25 -> 4450.99
B26: 2023/7 | C26: julho | D26: =SUMIF(Entradas!B:B,B26,Entradas!C:C) -> 11471.25 | E26: =SUM(F26:O26) -> 5784.28 | F26: =SUMIFS(Despesas!$C:$C,Despesas!$B:$B,$B26,Despesas!$E:$E,F$3) -> 50 | G26: =SUMIFS(Despesas!$C:$C,Despesas!$B:$B,$B26,Despesas!$E:$E,G$3) -> 0 | H26: =SUMIFS(Despesas!$C:$C,Despesas!$B:$B,$B26,Despesas!$E:$E,H$3) -> 529.72 | I26: =SUMIFS(Despesas!$C:$C,Despesas!$B:$B,$B26,Despesas!$E:$E,I$3) -> 249 | J26: =SUMIFS(Despesas!$C:$C,Despesas!$B:$B,$B26,Despesas!$E:$E,J$3) -> 239 | K26: =SUMIFS(Despesas!$C:$C,Despesas!$B:$B,$B26,Despesas!$E:$E,K$3) -> 3642.9 | L26: =SUMIFS(Despesas!$C:$C,Despesas!$B:$B,$B26,Despesas!$E:$E,L$3) -> 720 | M26: =SUMIFS(Despesas!$C:$C,Despesas!$B:$B,$B26,Despesas!$E:$E,M$3) -> 211.73 | ... O26: =SUMIFS(Despesas!$C:$C,Despesas!$B:$B,$B26,Despesas!$E:$E,O$3) -> 0 | P26: =D26-E26 -> 5686.97
B27: 2023/8 | C27: agosto | D27: =SUMIF(Entradas!B:B,B27,Entradas!C:C) -> 18066.88 | E27: =SUM(F27:O27) -> 8728.21 | F27: =SUMIFS(Despesas!$C:$C,Despesas!$B:$B,$B27,Despesas!$E:$E,F$3) -> 85.16 | G27: =SUMIFS(Despesas!$C:$C,Despesas!$B:$B,$B27,Despesas!$E:$E,G$3) -> 0 | H27: =SUMIFS(Despesas!$C:$C,Despesas!$B:$B,$B27,Despesas!$E:$E,H$3) -> 529.72 | I27: =SUMIFS(Despesas!$C:$C,Despesas!$B:$B,$B27,Despesas!$E:$E,I$3) -> 249 | J27: =SUMIFS(Despesas!$C:$C,Despesas!$B:$B,$B27,Despesas!$E:$E,J$3) -> 231 | K27: =SUMIFS(Despesas!$C:$C,Despesas!$B:$B,$B27,Despesas!$E:$E,K$3) -> 3642.96 | L27: =SUMIFS(Despesas!$C:$C,Despesas!$B:$B,$B27,Despesas!$E:$E,L$3) -> 970 | M27: =SUMIFS(Despesas!$C:$C,Despesas!$B:$B,$B27,Despesas!$E:$E,M$3) -> 235.93 | ... O27: =SUMIFS(Despesas!$C:$C,Despesas!$B:$B,$B27,Despesas!$E:$E,O$3) -> 0 | P27: =D27-E27 -> 9338.67
B28: 2023/9 | C28: setembro | D28: =SUMIF(Entradas!B:B,B28,Entradas!C:C) -> 20177.74 | E28: =SUM(F28:O28) -> 6394.48 | F28: =SUMIFS(Despesas!$C:$C,Despesas!$B:$B,$B28,Despesas!$E:$E,F$3) -> 80 | G28: =SUMIFS(Despesas!$C:$C,Despesas!$B:$B,$B28,Despesas!$E:$E,G$3) -> 0 | H28: =SUMIFS(Despesas!$C:$C,Despesas!$B:$B,$B28,Despesas!$E:$E,H$3) -> 529.72 | I28: =SUMIFS(Despesas!$C:$C,Despesas!$B:$B,$B28,Despesas!$E:$E,I$3) -> 640.99 | J28: =SUMIFS(Despesas!$C:$C,Despesas!$B:$B,$B28,Despesas!$E:$E,J$3) -> 472.13 | K28: =SUMIFS(Despesas!$C:$C,Despesas!$B:$B,$B28,Despesas!$E:$E,K$3) -> 3651.4 | L28: =SUMIFS(Despesas!$C:$C,Despesas!$B:$B,$B28,Despesas!$E:$E,L$3) -> 840 | M28: =SUMIFS(Despesas!$C:$C,Despesas!$B:$B,$B28,Despesas!$E:$E,M$3) -> 180.24 | ... O28: =SUMIFS(Despesas!$C:$C,Despesas!$B:$B,$B28,Despesas!$E:$E,O$3) -> 0 | P28: =D28-E28 -> 13783.26
B29: 2023/10 | C29: outubro | D29: =SUMIF(Entradas!B:B,B29,Entradas!C:C) -> 23650 | E29: =SUM(F29:O29) -> 5942.14 | F29: =SUMIFS(Despesas!$C:$C,Despesas!$B:$B,$B29,Despesas!$E:$E,F$3) -> 116.53 | G29: =SUMIFS(Despesas!$C:$C,Despesas!$B:$B,$B29,Despesas!$E:$E,G$3) -> 0 | H29: =SUMIFS(Despesas!$C:$C,Despesas!$B:$B,$B29,Despesas!$E:$E,H$3) -> 181.5 | I29: =SUMIFS(Despesas!$C:$C,Despesas!$B:$B,$B29,Despesas!$E:$E,I$3) -> 263.86 | J29: =SUMIFS(Despesas!$C:$C,Despesas!$B:$B,$B29,Despesas!$E:$E,J$3) -> 254.4 | K29: =SUMIFS(Despesas!$C:$C,Despesas!$B:$B,$B29,Despesas!$E:$E,K$3) -> 3642.83 | L29: =SUMIFS(Despesas!$C:$C,Despesas!$B:$B,$B29,Despesas!$E:$E,L$3) -> 920 | M29: =SUMIFS(Despesas!$C:$C,Despesas!$B:$B,$B29,Despesas!$E:$E,M$3) -> 563.02 | ... O29: =SUMIFS(Despesas!$C:$C,Despesas!$B:$B,$B29,Despesas!$E:$E,O$3) -> 0 | P29: =D29-E29 -> 17707.86
B30: 2023/11 | C30: novembro | D30: =SUMIF(Entradas!B:B,B30,Entradas!C:C) -> 23470 | E30: =SUM(F30:O30) -> 6533.93 | F30: =SUMIFS(Despesas!$C:$C,Despesas!$B:$B,$B30,Despesas!$E:$E,F$3) -> 63 | G30: =SUMIFS(Despesas!$C:$C,Despesas!$B:$B,$B30,Despesas!$E:$E,G$3) -> 187.8 | H30: =SUMIFS(Despesas!$C:$C,Despesas!$B:$B,$B30,Despesas!$E:$E,H$3) -> 0 | I30: =SUMIFS(Despesas!$C:$C,Despesas!$B:$B,$B30,Despesas!$E:$E,I$3) -> 294.09 | J30: =SUMIFS(Despesas!$C:$C,Despesas!$B:$B,$B30,Despesas!$E:$E,J$3) -> 289.4 | K30: =SUMIFS(Despesas!$C:$C,Despesas!$B:$B,$B30,Despesas!$E:$E,K$3) -> 3681.26 | L30: =SUMIFS(Despesas!$C:$C,Despesas!$B:$B,$B30,Despesas!$E:$E,L$3) -> 1190 | M30: =SUMIFS(Despesas!$C:$C,Despesas!$B:$B,$B30,Despesas!$E:$E,M$3) -> 828.38 | ... O30: =SUMIFS(Despesas!$C:$C,Despesas!$B:$B,$B30,Despesas!$E:$E,O$3) -> 0 | P30: =D30-E30 -> 16936.07
B31: 2023/12 | C31: dezembro | D31: =SUMIF(Entradas!B:B,B31,Entradas!C:C) -> 19700 | E31: =SUM(F31:O31) -> 6689.78 | F31: =SUMIFS(Despesas!$C:$C,Despesas!$B:$B,$B31,Despesas!$E:$E,F$3) -> 97.01 | G31: =SUMIFS(Despesas!$C:$C,Despesas!$B:$B,$B31,Despesas!$E:$E,G$3) -> 0 | H31: =SUMIFS(Despesas!$C:$C,Despesas!$B:$B,$B31,Despesas!$E:$E,H$3) -> 0 | I31: =SUMIFS(Despesas!$C:$C,Despesas!$B:$B,$B31,Despesas!$E:$E,I$3) -> 279 | J31: =SUMIFS(Despesas!$C:$C,Despesas!$B:$B,$B31,Despesas!$E:$E,J$3) -> 238.62 | K31: =SUMIFS(Despesas!$C:$C,Despesas!$B:$B,$B31,Despesas!$E:$E,K$3) -> 3681.26 | L31: =SUMIFS(Despesas!$C:$C,Despesas!$B:$B,$B31,Despesas!$E:$E,L$3) -> 690 | M31: =SUMIFS(Despesas!$C:$C,Despesas!$B:$B,$B31,Despesas!$E:$E,M$3) -> 1703.89 | ... O31: =SUMIFS(Despesas!$C:$C,Despesas!$B:$B,$B31,Despesas!$E:$E,O$3) -> 0 | P31: =D31-E31 -> 13010.22
C32: Fluxo | D32: =SUM(D20:D31) -> 185738.98 | E32: =SUM(E20:E31) -> 118821.04 | F32: =SUM(F20:F31) -> 1049.7 | G32: =SUM(G20:G31) -> 1042.16 | H32: =SUM(H20:H31) -> 5313.84 | I32: =SUM(I20:I31) -> 4815.22 | J32: =SUM(J20:J31) -> 3538.01 | K32: =SUM(K20:K31) -> 46303 | ... P32: =SUM(P20:P31) -> 66917.94
F34: =F48/SUM($F48:$O48) -> 0.010001561 | G34: =G48/SUM($F48:$O48) -> 0.08725148 | H34: =H48/SUM($F48:$O48) -> 0.010446343 | I34: =I48/SUM($F48:$O48) -> 0.031779095 | J34: =J48/SUM($F48:$O48) -> 0.096668905 | K34: =K48/SUM($F48:$O48) -> 0.49802808 | L34: =L48/SUM($F48:$O48) -> 0.094299985 | M34: =M48/SUM($F48:$O48) -> 0.094286364 | ... O34: =O48/SUM($F48:$O48) -> 0
C35: 2024 | D35: =D19 -> Recebimentos | E35: =E19 -> Despesas | F35: =F19 -> Transporte | G35: =G19 -> Materiais | H35: =H19 -> Educação | I35: =I19 -> Marketing | J35: =J19 -> Empresa/CRP | K35: =K19 -> Aluguel | ... N35: =N19 -> Reforma | P35: =P19 -> Total
B36: 2024/1 | C36: janeiro | D36: =SUMIF(Entradas!B:B,B36,Entradas!C:C) -> 15930 | E36: =SUM(F36:O36) -> 6553.57 | F36: =SUMIFS(Despesas!$C:$C,Despesas!$B:$B,$B36,Despesas!$E:$E,F$3) -> 50 | G36: =SUMIFS(Despesas!$C:$C,Despesas!$B:$B,$B36,Despesas!$E:$E,G$3) -> 32 | H36: =SUMIFS(Despesas!$C:$C,Despesas!$B:$B,$B36,Despesas!$E:$E,H$3) -> 997 | I36: =SUMIFS(Despesas!$C:$C,Despesas!$B:$B,$B36,Despesas!$E:$E,I$3) -> 269 | J36: =SUMIFS(Despesas!$C:$C,Despesas!$B:$B,$B36,Despesas!$E:$E,J$3) -> 246.2 | K36: =SUMIFS(Despesas!$C:$C,Despesas!$B:$B,$B36,Despesas!$E:$E,K$3) -> 3895.11 | L36: =SUMIFS(Despesas!$C:$C,Despesas!$B:$B,$B36,Despesas!$E:$E,L$3) -> 600 | M36: =SUMIFS(Despesas!$C:$C,Despesas!$B:$B,$B36,Despesas!$E:$E,M$3) -> 464.26 | ... O36: =SUMIFS(Despesas!$C:$C,Despesas!$B:$B,$B36,Despesas!$E:$E,O$3) -> 0 | P36: =D36-E36 -> 9376.43
B37: 2024/2 | C37: fevereiro | D37: =SUMIF(Entradas!B:B,B37,Entradas!C:C) -> 25710 | E37: =SUM(F37:O37) -> 6573.42 | F37: =SUMIFS(Despesas!$C:$C,Despesas!$B:$B,$B37,Despesas!$E:$E,F$3) -> 100 | G37: =SUMIFS(Despesas!$C:$C,Despesas!$B:$B,$B37,Despesas!$E:$E,G$3) -> 0 | H37: =SUMIFS(Despesas!$C:$C,Despesas!$B:$B,$B37,Despesas!$E:$E,H$3) -> 0 | I37: =SUMIFS(Despesas!$C:$C,Despesas!$B:$B,$B37,Despesas!$E:$E,I$3) -> 274 | J37: =SUMIFS(Despesas!$C:$C,Despesas!$B:$B,$B37,Despesas!$E:$E,J$3) -> 902.43 | K37: =SUMIFS(Despesas!$C:$C,Despesas!$B:$B,$B37,Despesas!$E:$E,K$3) -> 3975.37 | L37: =SUMIFS(Despesas!$C:$C,Despesas!$B:$B,$B37,Despesas!$E:$E,L$3) -> 800 | M37: =SUMIFS(Despesas!$C:$C,Despesas!$B:$B,$B37,Despesas!$E:$E,M$3) -> 316.62 | ... O37: =SUMIFS(Despesas!$C:$C,Despesas!$B:$B,$B37,Despesas!$E:$E,O$3) -> 0 | P37: =D37-E37 -> 19136.58
B38: 2024/3 | C38: março | D38: =SUMIF(Entradas!B:B,B38,Entradas!C:C) -> 21254 | E38: =SUM(F38:O38) -> 5965.4 | F38: =SUMIFS(Despesas!$C:$C,Despesas!$B:$B,$B38,Despesas!$E:$E,F$3) -> 50 | G38: =SUMIFS(Despesas!$C:$C,Despesas!$B:$B,$B38,Despesas!$E:$E,G$3) -> 0 | H38: =SUMIFS(Despesas!$C:$C,Despesas!$B:$B,$B38,Despesas!$E:$E,H$3) -> 0 | I38: =SUMIFS(Despesas!$C:$C,Despesas!$B:$B,$B38,Despesas!$E:$E,I$3) -> 249 | J38: =SUMIFS(Despesas!$C:$C,Despesas!$B:$B,$B38,Despesas!$E:$E,J$3) -> 295.57 | K38: =SUMIFS(Despesas!$C:$C,Despesas!$B:$B,$B38,Despesas!$E:$E,K$3) -> 3975.27 | L38: =SUMIFS(Despesas!$C:$C,Despesas!$B:$B,$B38,Despesas!$E:$E,L$3) -> 850 | M38: =SUMIFS(Despesas!$C:$C,Despesas!$B:$B,$B38,Despesas!$E:$E,M$3) -> 545.56 | ... O38: =SUMIFS(Despesas!$C:$C,Despesas!$B:$B,$B38,Despesas!$E:$E,O$3) -> 0 | P38: =D38-E38 -> 15288.6
B39: 2024/4 | C39: abril | D39: =SUMIF(Entradas!B:B,B39,Entradas!C:C) -> 25153.45 | E39: =SUM(F39:O39) -> 10377.44 | F39: =SUMIFS(Despesas!$C:$C,Despesas!$B:$B,$B39,Despesas!$E:$E,F$3) -> 60 | G39: =SUMIFS(Despesas!$C:$C,Despesas!$B:$B,$B39,Despesas!$E:$E,G$3) -> 0 | H39: =SUMIFS(Despesas!$C:$C,Despesas!$B:$B,$B39,Despesas!$E:$E,H$3) -> 0 | I39: =SUMIFS(Despesas!$C:$C,Despesas!$B:$B,$B39,Despesas!$E:$E,I$3) -> 249 | J39: =SUMIFS(Despesas!$C:$C,Despesas!$B:$B,$B39,Despesas!$E:$E,J$3) -> 613.12 | K39: =SUMIFS(Despesas!$C:$C,Despesas!$B:$B,$B39,Despesas!$E:$E,K$3) -> 4060.02 | L39: =SUMIFS(Despesas!$C:$C,Despesas!$B:$B,$B39,Despesas!$E:$E,L$3) -> 800 | M39: =SUMIFS(Despesas!$C:$C,Despesas!$B:$B,$B39,Despesas!$E:$E,M$3) -> 728.68 | ... O39: =SUMIFS(Despesas!$C:$C,Despesas!$B:$B,$B39,Despesas!$E:$E,O$3) -> 0 | P39: =D39-E39 -> 14776.01
B40: 2024/5 | C40: maio | D40: =SUMIF(Entradas!B:B,B40,Entradas!C:C) -> 26466.9 | E40: =SUM(F40:O40) -> 7285.3 | F40: =SUMIFS(Despesas!$C:$C,Despesas!$B:$B,$B40,Despesas!$E:$E,F$3) -> 70 | G40: =SUMIFS(Despesas!$C:$C,Despesas!$B:$B,$B40,Despesas!$E:$E,G$3) -> 0 | H40: =SUMIFS(Despesas!$C:$C,Despesas!$B:$B,$B40,Despesas!$E:$E,H$3) -> 0 | I40: =SUMIFS(Despesas!$C:$C,Despesas!$B:$B,$B40,Despesas!$E:$E,I$3) -> 249 | J40: =SUMIFS(Despesas!$C:$C,Despesas!$B:$B,$B40,Despesas!$E:$E,J$3) -> 309.2 | K40: =SUMIFS(Despesas!$C:$C,Despesas!$B:$B,$B40,Despesas!$E:$E,K$3) -> 3953.26 | L40: =SUMIFS(Despesas!$C:$C,Despesas!$B:$B,$B40,Despesas!$E:$E,L$3) -> 300 | M40: =SUMIFS(Despesas!$C:$C,Despesas!$B:$B,$B40,Despesas!$E:$E,M$3) -> 703.84 | ... O40: =SUMIFS(Despesas!$C:$C,Despesas!$B:$B,$B40,Despesas!$E:$E,O$3) -> 0 | P40: =D40-E40 -> 19181.6
B41: 2024/6 | C41: junho | D41: =SUMIF(Entradas!B:B,B41,Entradas!C:C) -> 30623.45 | E41: =SUM(F41:O41) -> 6505.78 | F41: =SUMIFS(Despesas!$C:$C,Despesas!$B:$B,$B41,Despesas!$E:$E,F$3) -> 64.55 | G41: =SUMIFS(Despesas!$C:$C,Despesas!$B:$B,$B41,Despesas!$E:$E,G$3) -> 0 | H41: =SUMIFS(Despesas!$C:$C,Despesas!$B:$B,$B41,Despesas!$E:$E,H$3) -> 0 | I41: =SUMIFS(Despesas!$C:$C,Despesas!$B:$B,$B41,Despesas!$E:$E,I$3) -> 249 | J41: =SUMIFS(Despesas!$C:$C,Despesas!$B:$B,$B41,Despesas!$E:$E,J$3) -> 672.12 | K41: =SUMIFS(Despesas!$C:$C,Despesas!$B:$B,$B41,Despesas!$E:$E,K$3) -> 3953.26 | L41: =SUMIFS(Despesas!$C:$C,Despesas!$B:$B,$B41,Despesas!$E:$E,L$3) -> 750 | M41: =SUMIFS(Despesas!$C:$C,Despesas!$B:$B,$B41,Despesas!$E:$E,M$3) -> 816.85 | ... O41: =SUMIFS(Despesas!$C:$C,Despesas!$B:$B,$B41,Despesas!$E:$E,O$3) -> 0 | P41: =D41-E41 -> 24117.67
B42: 2024/7 | C42: julho | D42: =SUMIF(Entradas!B:B,B42,Entradas!C:C) -> 27510 | E42: =SUM(F42:O42) -> 6656.1 | F42: =SUMIFS(Despesas!$C:$C,Despesas!$B:$B,$B42,Despesas!$E:$E,F$3) -> 100 | G42: =SUMIFS(Despesas!$C:$C,Despesas!$B:$B,$B42,Despesas!$E:$E,G$3) -> 0 | H42: =SUMIFS(Despesas!$C:$C,Despesas!$B:$B,$B42,Despesas!$E:$E,H$3) -> 0 | I42: =SUMIFS(Despesas!$C:$C,Despesas!$B:$B,$B42,Despesas!$E:$E,I$3) -> 249 | J42: =SUMIFS(Despesas!$C:$C,Despesas!$B:$B,$B42,Despesas!$E:$E,J$3) -> 1203.04 | K42: =SUMIFS(Despesas!$C:$C,Despesas!$B:$B,$B42,Despesas!$E:$E,K$3) -> 3953.26 | L42: =SUMIFS(Despesas!$C:$C,Despesas!$B:$B,$B42,Despesas!$E:$E,L$3) -> 700 | M42: =SUMIFS(Despesas!$C:$C,Despesas!$B:$B,$B42,Despesas!$E:$E,M$3) -> 450.8 | ... O42: =SUMIFS(Despesas!$C:$C,Despesas!$B:$B,$B42,Despesas!$E:$E,O$3) -> 0 | P42: =D42-E42 -> 20853.9
B43: 2024/8 | C43: agosto | D43: =SUMIF(Entradas!B:B,B43,Entradas!C:C) -> 28065 | E43: =SUM(F43:O43) -> 7116.86 | F43: =SUMIFS(Despesas!$C:$C,Despesas!$B:$B,$B43,Despesas!$E:$E,F$3) -> 80 | G43: =SUMIFS(Despesas!$C:$C,Despesas!$B:$B,$B43,Despesas!$E:$E,G$3) -> 0 | H43: =SUMIFS(Despesas!$C:$C,Despesas!$B:$B,$B43,Despesas!$E:$E,H$3) -> 0 | I43: =SUMIFS(Despesas!$C:$C,Despesas!$B:$B,$B43,Despesas!$E:$E,I$3) -> 249 | J43: =SUMIFS(Despesas!$C:$C,Despesas!$B:$B,$B43,Despesas!$E:$E,J$3) -> 882.04 | K43: =SUMIFS(Despesas!$C:$C,Despesas!$B:$B,$B43,Despesas!$E:$E,K$3) -> 3953.26 | L43: =SUMIFS(Despesas!$C:$C,Despesas!$B:$B,$B43,Despesas!$E:$E,L$3) -> 1150 | M43: =SUMIFS(Despesas!$C:$C,Despesas!$B:$B,$B43,Despesas!$E:$E,M$3) -> 802.56 | ... O43: =SUMIFS(Despesas!$C:$C,Despesas!$B:$B,$B43,Despesas!$E:$E,O$3) -> 0 | P43: =D43-E43 -> 20948.14
...

Sheet Entradas
C1: =IF(SUM(C3:C995)=0,"",SUM(C3:C995)) -> 752394.88 | E1: =IF(SUM(E3:E995)=0,"",SUM(E3:E995)) -> 4250 | F1: =IF(SUM(F3:F995)=0,"",SUM(F3:F995)) -> 300 | G1: =IF(SUM(G3:G995)=0,"",SUM(G3:G995)) -> 900 | H1: =IF(SUM(H3:H995)=0,"",SUM(H3:H995)) -> 150 | I1: =IF(SUM(I3:I995)=0,"",SUM(I3:I995)) -> 150 | J1: =IF(SUM(J3:J995)=0,"",SUM(J3:J995)) -> 150 | K1: =IF(SUM(K3:K995)=0,"",SUM(K3:K995)) -> 150 | L1: =IF(SUM(L3:L995)=0,"",SUM(L3:L995)) -> 150 | ... EC1: =IF(SUM(EC3:EC995)=0,"",SUM(EC3:EC995)) -> 1500 | EE1: =IF(SUM(EE3:EE995)=0,"",SUM(EE3:EE995)) -> 46429
C2: Recebido No Dia | D2: Data | E2: Flávio | F2: João | G2: Mariane | H2: Mariana Menezes | I2: Isaac | J2: Thyara (Wallyson) | K2: Daniel Berg | L2: Paulo Luz | M2: Gustavo | N2: Thales | O2: Andre Junio | P2: Matheus Av Neuro | Q2: Polliani | R2: Vctor Morato | S2: Estelita | T2: Maria Aparecida | U2: Pedro Av neuro | V2: Davi Lucas | W2: Thaís Couto | X2: José W. Av Neuro | Y2: Carlos Augusto | Z2: Italo vactomia | AA2: Aredson | AB2: Beatriz Av neuro | AC2: Diogo Alberto AV. Neuro | AD2: Bruno | AE2: Jefferson | AF2: Caio | AG2: Ivone | AH2: Juscelia | AI2: Luana Godinho | AJ2: Elisa | AK2: Yuri | AL2: Luiz Felipe Av neuro | AM2: Tatiane | AN2: Aurélio | AO2: Arthur Av. Neuro | AP2: Ana Paula | AQ2: Stela | AR2: Ayke | AS2: Vitória | AT2: Neivander | AU2: Jaqueline | AV2: Mateus Av neuro | AW2: Vinicius Garcês | AX2: Alerte | AY2: Fabiano | AZ2: FACULDADE | BA2: Jhessica | BB2: Eurico | BC2: Suyara Av neuro | BD2: Terezinha Maria | BE2: Nayara de Souza | BF2: Ana Carolina Caio | BG2: Paula Amorim | BH2: Anna Flávia | BI2: Thais av | BJ2: Jordana | BK2: Flaviany | BL2: Jarbas | BM2: Arthur Apolo Av. neuro | BN2: Joseane | BO2: Marcelo Cardoso | BP2: Paulo H. Pinheiro | BQ2: Luisa Leal Gomes | BR2: Miriane | BS2: Amanda | BT2: Larissa Silva | BU2: Paulo Pinho | BV2: Estefânia | BW2: Rosimere | BX2: João Guilherme | BY2: Renata Dias | BZ2: Júlia Olegario | CA2: João Luiz | CB2: Leandro | CC2: Constância | CD2: Lucimeire | CE2: Ricardo | CF2: Renata Ribeiro | CG2: Cleide | CH2: Renata Gonçalves | CI2: Alexandra | CJ2: Élida | CK2: Valcy | CL2: Júlia | CM2: Luanna (mãe de Marianna) | CN2: Gabriel | CO2: Alinne | CP2: Alexandre | CQ2: Nátalia | CR2: Wesley | CS2: Marianna | CT2: Ludmilla | CU2: Luana | CV2: Allyson | CW2: Gercina | CX2: Caio Dornelas Av neuro | CY2: Silvana | CZ2: Luiza | DA2: Lenira Av neuro | DB2: Núbia | DC2: Renata Av neuro | DD2: Cleidlene | DE2: Witian | DF2: Nathalia | DG2: Vitória Av neuro | DH2: Mayara | DI2: Ávila (mae Rosana) | DJ2: Ana Laura (Pacoquinha) | DK2: Nilda | DL2: Tatiana | DM2: Heitor (pai Alessandro) | DN2: Gilbrair | DO2: Ariadna | DP2: Ana karolina Lucimeire | DQ2: Vanessa | DR2: Isabel | DS2: Mathilde | DT2: Yara Kelly | DU2: Victor Queiroz | DV2: Miguel | DW2: Hannanh | DX2: Maria Laura Av Neuro | DY2: Geovanna | DZ2: Juliana | EA2: Klaus | EB2: Murillo | EC2: Marcus | EE2: Sublocação
B3: =IF(D3>0, CONCATENATE(YEAR(D3),"/",MONTH(D3)),"") -> 2022/1 | C3: =IF(SUM(E3:EG3)=0,"",SUM(E3:EG3)) -> 50 | D3: 44585 | F3: 50
B4: =IF(D4>0, CONCATENATE(YEAR(D4),"/",MONTH(D4)),"") -> 2022/2 | C4: =IF(SUM(E4:EG4)=0,"",SUM(E4:EG4)) -> 150 | D4: 44599 | G4: 150
B5: =IF(D5>0, CONCATENATE(YEAR(D5),"/",MONTH(D5)),"") -> 2022/2 | C5: =IF(SUM(E5:EG5)=0,"",SUM(E5:EG5)) -> 200 | D5: 44620 | F5: 50 | G5: 150
B6: =IF(D6>0, CONCATENATE(YEAR(D6),"/",MONTH(D6)),"") -> 2022/3 | C6: =IF(SUM(E6:EG6)=0,"",SUM(E6:EG6)) -> 150 | D6: 44628 | N6: 150
B7: =IF(D7>0, CONCATENATE(YEAR(D7),"/",MONTH(D7)),"") -> 2022/3 | C7: =IF(SUM(E7:EG7)=0,"",SUM(E7:EG7)) -> 150 | D7: 44630 | N7: 150
B8: =IF(D8>0, CONCATENATE(YEAR(D8),"/",MONTH(D8)),"") -> 2022/3 | C8: =IF(SUM(E8:EG8)=0,"",SUM(E8:EG8)) -> 150 | D8: 44631 | CZ8: 150
B9: =IF(D9>0, CONCATENATE(YEAR(D9),"/",MONTH(D9)),"") -> 2022/3 | C9: =IF(SUM(E9:EG9)=0,"",SUM(E9:EG9)) -> 350 | D9: 44634 | F9: 50 | AJ9: 300
B10: =IF(D10>0, CONCATENATE(YEAR(D10),"/",MONTH(D10)),"") -> 2022/3 | C10: =IF(SUM(E10:EG10)=0,"",SUM(E10:EG10)) -> 150 | D10: 44637 | CZ10: 150
B11: =IF(D11>0, CONCATENATE(YEAR(D11),"/",MONTH(D11)),"") -> 2022/3 | C11: =IF(SUM(E11:EG11)=0,"",SUM(E11:EG11)) -> 450 | D11: 44644 | N11: 300 | CZ11: 150
B12: =IF(D12>0, CONCATENATE(YEAR(D12),"/",MONTH(D12)),"") -> 2022/3 | C12: =IF(SUM(E12:EG12)=0,"",SUM(E12:EG12)) -> 195 | D12: 44649 | N12: 195
B13: =IF(D13>0, CONCATENATE(YEAR(D13),"/",MONTH(D13)),"") -> 2022/3 | C13: =IF(SUM(E13:EG13)=0,"",SUM(E13:EG13)) -> 150 | D13: 44651 | AQ13: 150
B14: =IF(D14>0, CONCATENATE(YEAR(D14),"/",MONTH(D14)),"") -> 2022/4 | C14: =IF(SUM(E14:EG14)=0,"",SUM(E14:EG14)) -> 150 | D14: 44655 | H14: 150
B15: =IF(D15>0, CONCATENATE(YEAR(D15),"/",MONTH(D15)),"") -> 2022/4 | C15: =IF(SUM(E15:EG15)=0,"",SUM(E15:EG15)) -> 450 | D15: 44658 | AQ15: 300 | CZ15: 150
B16: =IF(D16>0, CONCATENATE(YEAR(D16),"/",MONTH(D16)),"") -> 2022/4 | C16: =IF(SUM(E16:EG16)=0,"",SUM(E16:EG16)) -> 450 | D16: 44662 | N16: 150 | AF16: 300
B17: =IF(D17>0, CONCATENATE(YEAR(D17),"/",MONTH(D17)),"") -> 2022/4 | C17: =IF(SUM(E17:EG17)=0,"",SUM(E17:EG17)) -> 150 | D17: 44664 | AQ17: 150
B18: =IF(D18>0, CONCATENATE(YEAR(D18),"/",MONTH(D18)),"") -> 2022/4 | C18: =IF(SUM(E18:EG18)=0,"",SUM(E18:EG18)) -> 150 | D18: 44665 | CZ18: 150
B19: =IF(D19>0, CONCATENATE(YEAR(D19),"/",MONTH(D19)),"") -> 2022/4 | C19: =IF(SUM(E19:EG19)=0,"",SUM(E19:EG19)) -> 200 | D19: 44669 | F19: 50 | G19: 150
B20: =IF(D20>0, CONCATENATE(YEAR(D20),"/",MONTH(D20)),"") -> 2022/4 | C20: =IF(SUM(E20:EG20)=0,"",SUM(E20:EG20)) -> 600 | D20: 44670 | N20: 300 | AJ20: 300
B21: =IF(D21>0, CONCATENATE(YEAR(D21),"/",MONTH(D21)),"") -> 2022/4 | C21: =IF(SUM(E21:EG21)=0,"",SUM(E21:EG21)) | D21: 44676
B22: =IF(D22>0, CONCATENATE(YEAR(D22),"/",MONTH(D22)),"") -> 2022/4 | C22: =IF(SUM(E22:EG22)=0,"",SUM(E22:EG22)) -> 150 | D22: 44677 | CZ22: 150
B23: =IF(D23>0, CONCATENATE(YEAR(D23),"/",MONTH(D23)),"") -> 2022/4 | C23: =IF(SUM(E23:EG23)=0,"",SUM(E23:EG23)) -> 150 | D23: 44679 | G23: Não 150 | AQ23: 150
B24: =IF(D24>0, CONCATENATE(YEAR(D24),"/",MONTH(D24)),"") -> 2022/5 | C24: =IF(SUM(E24:EG24)=0,"",SUM(E24:EG24)) -> 200 | D24: 44683 | F24: 50 | G24: 150
B25: =IF(D25>0, CONCATENATE(YEAR(D25),"/",MONTH(D25)),"") -> 2022/5 | C25: =IF(SUM(E25:EG25)=0,"",SUM(E25:EG25)) -> 750 | D25: 44686 | N25: 300 | AF25: 450
B26: =IF(D26>0, CONCATENATE(YEAR(D26),"/",MONTH(D26)),"") -> 2022/5 | C26: =IF(SUM(E26:EG26)=0,"",SUM(E26:EG26)) | D26: 44687
B27: =IF(D27>0, CONCATENATE(YEAR(D27),"/",MONTH(D27)),"") -> 2022/5 | C27: =IF(SUM(E27:EG27)=0,"",SUM(E27:EG27)) -> 300 | D27: 44690 | AQ27: 150 | CZ27: 150
B28: =IF(D28>0, CONCATENATE(YEAR(D28),"/",MONTH(D28)),"") -> 2022/5 | C28: =IF(SUM(E28:EG28)=0,"",SUM(E28:EG28)) -> 300 | D28: 44693 | AJ28: 300
B29: =IF(D29>0, CONCATENATE(YEAR(D29),"/",MONTH(D29)),"") -> 2022/5 | C29: =IF(SUM(E29:EG29)=0,"",SUM(E29:EG29)) -> 150 | D29: 44694 | AQ29: 150
B30: =IF(D30>0, CONCATENATE(YEAR(D30),"/",MONTH(D30)),"") -> 2022/5 | C30: =IF(SUM(E30:EG30)=0,"",SUM(E30:EG30)) -> 150 | D30: 44697 | CF30: 150
B31: =IF(D31>0, CONCATENATE(YEAR(D31),"/",MONTH(D31)),"") -> 2022/5 | C31: =IF(SUM(E31:EG31)=0,"",SUM(E31:EG31)) | D31: 44700
B32: =IF(D32>0, CONCATENATE(YEAR(D32),"/",MONTH(D32)),"") -> 2022/5 | C32: =IF(SUM(E32:EG32)=0,"",SUM(E32:EG32)) -> 750 | D32: 44707 | I32: 150 | AN32: 150 | CF32: 450
B33: =IF(D33>0, CONCATENATE(YEAR(D33),"/",MONTH(D33)),"") -> 2022/5 | C33: =IF(SUM(E33:EG33)=0,"",SUM(E33:EG33)) -> 300 | D33: 44708 | N33: 150 | AQ33: 150
B34: =IF(D34>0, CONCATENATE(YEAR(D34),"/",MONTH(D34)),"") -> 2022/5 | C34: =IF(SUM(E34:EG34)=0,"",SUM(E34:EG34)) -> 150 | D34: 44711 | J34: 150
B35: =IF(D35>0, CONCATENATE(YEAR(D35),"/",MONTH(D35)),"") -> 2022/5 | C35: =IF(SUM(E35:EG35)=0,"",SUM(E35:EG35)) -> 300 | D35: 44712 | AN35: 150 | CZ35: 150
B36: =IF(D36>0, CONCATENATE(YEAR(D36),"/",MONTH(D36)),"") -> 2022/6 | C36: =IF(SUM(E36:EG36)=0,"",SUM(E36:EG36)) -> 150 | D36: 44713 | K36: 150
B37: =IF(D37>0, CONCATENATE(YEAR(D37),"/",MONTH(D37)),"") -> 2022/6 | C37: =IF(SUM(E37:EG37)=0,"",SUM(E37:EG37)) | D37: 44715
B38: =IF(D38>0, CONCATENATE(YEAR(D38),"/",MONTH(D38)),"") -> 2022/6 | C38: =IF(SUM(E38:EG38)=0,"",SUM(E38:EG38)) -> 150 | D38: 44718 | L38: 150
B39: =IF(D39>0, CONCATENATE(YEAR(D39),"/",MONTH(D39)),"") -> 2022/6 | C39: =IF(SUM(E39:EG39)=0,"",SUM(E39:EG39)) -> 600 | D39: 44719 | AF39: 600
B40: =IF(D40>0, CONCATENATE(YEAR(D40),"/",MONTH(D40)),"") -> 2022/6 | C40: =IF(SUM(E40:EG40)=0,"",SUM(E40:EG40)) -> 600 | D40: 44721 | CF40: 600
...

Sheet Despesas
B2: Invest. | C2: Valor | D2: Data | E2: Tipo | F2: Observação
B3: =IF(D3>0, CONCATENATE(YEAR(D3),"/",MONTH(D3)),"") -> 2022/1 | C3: 48.3 | D3: 44567 | E3: Marketing
B4: =IF(D4>0, CONCATENATE(YEAR(D4),"/",MONTH(D4)),"") -> 2022/1 | C4: 30 | D4: 44567 | E4: Materiais
B5: =IF(D5>0, CONCATENATE(YEAR(D5),"/",MONTH(D5)),"") -> 2022/1 | C5: 529.72 | D5: 44571 | E5: Educação
B6: =IF(D6>0, CONCATENATE(YEAR(D6),"/",MONTH(D6)),"") -> 2022/1 | C6: 11 | D6: 44578 | E6: Transporte
B7: =IF(D7>0, CONCATENATE(YEAR(D7),"/",MONTH(D7)),"") -> 2022/1 | C7: 6 | D7: 44578 | E7: Transporte
B8: =IF(D8>0, CONCATENATE(YEAR(D8),"/",MONTH(D8)),"") -> 2022/1 | C8: 86.3 | D8: 44581 | E8: Materiais
B9: =IF(D9>0, CONCATENATE(YEAR(D9),"/",MONTH(D9)),"") -> 2022/1 | C9: 30.11 | D9: 44582 | E9: Materiais
B10: =IF(D10>0, CONCATENATE(YEAR(D10),"/",MONTH(D10)),"") -> 2022/1 | C10: 50 | D10: 44582 | E10: Marketing
B11: =IF(D11>0, CONCATENATE(YEAR(D11),"/",MONTH(D11)),"") -> 2022/1 | C11: 50 | D11: 44585 | E11: Recebimentos | F11: João (valor mensal simbólico)
B12: =IF(D12>0, CONCATENATE(YEAR(D12),"/",MONTH(D12)),"") -> 2022/1 | C12: 33.73 | D12: 44585 | E12: Transporte
B13: =IF(D13>0, CONCATENATE(YEAR(D13),"/",MONTH(D13)),"") -> 2022/1 | C13: 666.16 | D13: 44585 | E13: Empresa/CRP
B14: =IF(D14>0, CONCATENATE(YEAR(D14),"/",MONTH(D14)),"") -> 2022/1 | C14: 33.1 | D14: 44592 | E14: Transporte
B15: =IF(D15>0, CONCATENATE(YEAR(D15),"/",MONTH(D15)),"") -> 2022/1 | C15: 400 | D15: 44592 | E15: Aluguel
B16: =IF(D16>0, CONCATENATE(YEAR(D16),"/",MONTH(D16)),"") -> 2022/2 | C16: 51.09 | D16: 44594 | E16: Materiais
B17: =IF(D17>0, CONCATENATE(YEAR(D17),"/",MONTH(D17)),"") -> 2022/2 | C17: 24.15 | D17: 44598 | E17: Marketing | F17: canva
B18: =IF(D18>0, CONCATENATE(YEAR(D18),"/",MONTH(D18)),"") -> 2022/2 | C18: 16 | D18: 44599 | E18: Transporte
B19: =IF(D19>0, CONCATENATE(YEAR(D19),"/",MONTH(D19)),"") -> 2022/2 | C19: 150 | D19: 44599 | E19: Recebimentos | F19: Mariane - 1° parcela de fevereiro da (total mensal de 300 - 50% desconto)
B20: =IF(D20>0, CONCATENATE(YEAR(D20),"/",MONTH(D20)),"") -> 2022/2 | C20: 529.72 | D20: 44602 | E20: Educação
B21: =IF(D21>0, CONCATENATE(YEAR(D21),"/",MONTH(D21)),"") -> 2022/2 | C21: 289 | D21: 44610 | E21: Marketing | F21: doctoralia
B22: =IF(D22>0, CONCATENATE(YEAR(D22),"/",MONTH(D22)),"") -> 2022/2 | C22: 20.96 | D22: 44616 | E22: Materiais
B23: =IF(D23>0, CONCATENATE(YEAR(D23),"/",MONTH(D23)),"") -> 2022/2 | C23: 20.96 | D23: 44616 | E23: Materiais
B24: =IF(D24>0, CONCATENATE(YEAR(D24),"/",MONTH(D24)),"") -> 2022/2 | C24: 6 | D24: 44620 | E24: Transporte
B25: =IF(D25>0, CONCATENATE(YEAR(D25),"/",MONTH(D25)),"") -> 2022/2 | C25: 400 | D25: 44620 | E25: Aluguel
B26: =IF(D26>0, CONCATENATE(YEAR(D26),"/",MONTH(D26)),"") -> 2022/2 | C26: 150 | D26: 44620 | E26: Recebimentos | F26: Mariane - 2° parcela de fevereiro (pag atrasado 08/03)
B27: =IF(D27>0, CONCATENATE(YEAR(D27),"/",MONTH(D27)),"") -> 2022/2 | C27: 50 | D27: 44620 | E27: Recebimentos | F27: João (valor mensal simbólico)
B28: =IF(D28>0, CONCATENATE(YEAR(D28),"/",MONTH(D28)),"") -> 2022/2 | C28: 200 | D28: 44620 | E28: Empresa/CRP | F28: contador
B29: =IF(D29>0, CONCATENATE(YEAR(D29),"/",MONTH(D29)),"") -> 2022/3 | C29: 49.07 | D29: 44623 | E29: Materiais
B30: =IF(D30>0, CONCATENATE(YEAR(D30),"/",MONTH(D30)),"") -> 2022/3 | C30: 240 | D30: 44624 | E30: Aluguel
B31: =IF(D31>0, CONCATENATE(YEAR(D31),"/",MONTH(D31)),"") -> 2022/3 | C31: 20 | D31: 44627 | E31: Transporte
B32: =IF(D32>0, CONCATENATE(YEAR(D32),"/",MONTH(D32)),"") -> 2022/3 | C32: 16 | D32: 44628 | E32: Transporte
B33: =IF(D33>0, CONCATENATE(YEAR(D33),"/",MONTH(D33)),"") -> 2022/3 | C33: 150 | D33: 44628 | E33: Recebimentos | F33: Thales - valor da sessão
B34: =IF(D34>0, CONCATENATE(YEAR(D34),"/",MONTH(D34)),"") -> 2022/3 | C34: 150 | D34: 44630 | E34: Recebimentos | F34: Thales - valor da sessão
B35: =IF(D35>0, CONCATENATE(YEAR(D35),"/",MONTH(D35)),"") -> 2022/3 | C35: 20 | D35: 44630 | E35: Transporte
B36: =IF(D36>0, CONCATENATE(YEAR(D36),"/",MONTH(D36)),"") -> 2022/3 | C36: 529.72 | D36: 44630 | E36: Educação
B37: =IF(D37>0, CONCATENATE(YEAR(D37),"/",MONTH(D37)),"") -> 2022/3 | C37: 200 | D37: 44630 | E37: Empresa/CRP
B38: =IF(D38>0, CONCATENATE(YEAR(D38),"/",MONTH(D38)),"") -> 2022/3 | C38: 150 | D38: 44631 | E38: Recebimentos | F38: Luiza - valor da sessão da mãe
B39: =IF(D39>0, CONCATENATE(YEAR(D39),"/",MONTH(D39)),"") -> 2022/3 | C39: 16 | D39: 44634 | E39: Transporte
B40: =IF(D40>0, CONCATENATE(YEAR(D40),"/",MONTH(D40)),"") -> 2022/3 | C40: 50 | D40: 44634 | E40: Recebimentos | F40: João (valor mensal simbólico)
B41: =IF(D41>0, CONCATENATE(YEAR(D41),"/",MONTH(D41)),"") -> 2022/3 | C41: 300 | D41: 44634 | E41: Recebimentos | F41: Elisa (valor mensal com 50% de desconto online, 17/02 a 14/03 - 4 sessões)
...

Sheet Informações
B2: Classe | C2: Paciente | D2: Tratamento | E2: Data de Nascimento | F2: Idade | G2: Iniciou | H2: Fim | I2: Tempo de Terapia | J2: Telefone | K2: Profissão | L2: Contato de Emergência | M2: Nome | N2: E-mail | O2: Endereço | P2: Bairro | Q2: Cidade | R2: CEP | S2: Nome do Pai | T2: Nome da Mãe | U2: finalizou | V2: CPF | W2: Origem | X2: Observações
A3: =IF(E3<>0, MONTH(E3),"") -> 9 | B3: =IF(F3="","", IF(F3<12,"Criança",IF(F3<18,"Adolescente",IF(F3<26,"Jovem",IF(F3<60,"Adulto", "Idoso"))))) -> Adolescente | C3: João Pedro Cardoso de Oliveira | D3: Terapia | E3: 40443 | F3: =IF(E3>0, DATEDIF(E3,TODAY(),"Y"),"") -> 15 | G3: 44592 | H3: =IF(U3>0,U3,TODAY()) -> 44755 | I3: =IF(G3>0, ROUNDDOWN((H3-G3)/365,0)& " Anos e "& ROUNDDOWN(((H3-G3)-ROUNDDOWN((H3-G3)/365,0)*365)/30,0)&" meses","") -> 0 Anos e 5 meses | J3: 62 991135413 | K3: estudante | L3: 63 991135413 | M3: tia vó Maria | N3: rosariooliveira270452@gmail.com | O3: Av. Cândido Portinari Qd. 57, Lt. 12 | P3: St. Gentil Meirelles | Q3: Goiânia | S3: Wander Telis Cardoso | T3: Cristina Melo de Oliveira | U3: 44755 | W3: estágio da puc/outro | X3: valor social do estágio da puc - deficiência intelectual e TDAH
A4: =IF(E4<>0, MONTH(E4),"") -> 7 | B4: Adolescente | C4: Ioshua de Santana Santos | D4: Terapia | E4: 38187 | F4: =IF(E4>0, DATEDIF(E4,TODAY(),"Y"),"") -> 21 | G4: 44592 | H4: =IF(U4>0,U4,TODAY()) -> 44755 | I4: =IF(G4>0, ROUNDDOWN((H4-G4)/365,0)& " Anos e "& ROUNDDOWN(((H4-G4)-ROUNDDOWN((H4-G4)/365,0)*365)/30,0)&" meses","") -> 0 Anos e 5 meses | J4: 62 981553961 | K4: estudante | L4: 63 981553961/ 6299314 0718 | M4: mãe/pai | N4: ioshua.santos@outlook.com | O4: Rua Bauru Quadra 25 Lote 02 | P4: Jd. Novo Mundo | Q4: Goiânia | R4: 74715-070 | S4: Paulo César Gonçalves Santos | T4: Maria Lucilene de Santana | U4: 44755 | W4: estágio da puc/outro | X4: valor social do estágio da puc
A5: =IF(E5<>0, MONTH(E5),"") -> 9 | B5: =IF(F5="","", IF(F5<12,"Criança",IF(F5<18,"Adolescente",IF(F5<26,"Jovem",IF(F5<60,"Adulto", "Idoso"))))) -> Adulto | C5: Mariane Rezende Magalhães | D5: Terapia | E5: 35675 | F5: =IF(E5>0, DATEDIF(E5,TODAY(),"Y"),"") -> 28 | G5: 44592 | H5: =IF(U5>0,U5,TODAY()) -> 44719 | I5: =IF(G5>0, ROUNDDOWN((H5-G5)/365,0)& " Anos e "& ROUNDDOWN(((H5-G5)-ROUNDDOWN((H5-G5)/365,0)*365)/30,0)&" meses","") -> 0 Anos e 4 meses | J5: 62 999361248 | K5: engenheiro civil | L5: 62 999652885 | M5: mãe Mária | N5: marianemaggs@gmail.com | O5: Rua das Paineiras, Qd. 67, Lt. 16, casa 2 | P5: Jardim Mariliza | Q5: Goiânia | R5: 74885-340 | S5: Arlindo Magalhães Filho | T5: Márcia Morais Rezende Magalhães | U5: 44719 | W5: Indicação amigo Marcelo | X5: valor social
A6: =IF(E6<>0, MONTH(E6),"") -> 6 | B6: =IF(F6="","", IF(F6<12,"Criança",IF(F6<18,"Adolescente",IF(F6<26,"Jovem",IF(F6<60,"Adulto", "Idoso"))))) -> Adulto | C6: Thales Rafael Gomes de Castro | D6: Terapia | E6: 34142 | F6: =IF(E6>0, DATEDIF(E6,TODAY(),"Y"),"") -> 32 | G6: 44628 | H6: =IF(U6>0,U6,TODAY()) -> 44855 | I6: =IF(G6>0, ROUNDDOWN((H6-G6)/365,0)& " Anos e "& ROUNDDOWN(((H6-G6)-ROUNDDOWN((H6-G6)/365,0)*365)/30,0)&" meses","") -> 0 Anos e 7 meses | J6: 62 998158180 | K6: engenheiro civil | L6: 62 996370517 | M6: pai José Henrique | N6: akiamacastro@gmail.com | O6: Rua S4, 20 - Ed. Resi. dos girrassóis, ap 700 | P6: St. Bela vista | Q6: Goiânia | S6: José Henrique | U6: 44855 | W6: doctoralia
A7: =IF(E7<>0, MONTH(E7),"") -> 11 | B7: =IF(F7="","", IF(F7<12,"Criança",IF(F7<18,"Adolescente",IF(F7<26,"Jovem",IF(F7<60,"Adulto", "Idoso"))))) -> Jovem | C7: Elisa Nunes de Castro Borges | D7: Terapia | E7: 37942 | F7: =IF(E7>0, DATEDIF(E7,TODAY(),"Y"),"") -> 22 | G7: 44609 | H7: =IF(U7>0,U7,TODAY()) -> 44994 | I7: =IF(G7>0, ROUNDDOWN((H7-G7)/365,0)& " Anos e "& ROUNDDOWN(((H7-G7)-ROUNDDOWN((H7-G7)/365,0)*365)/30,0)&" meses","") -> 1 Anos e 0 meses | J7: 64 996718220 | K7: estudante - computação | L7: 64 996956863 | M7: mãe Cristiane | N7: elisancb096@gmail.com | O7: Avenida: Contorno, Quadra: 36, Lote: 21 | P7: Santa Maria | Q7: Arizona/GO | R7: 75280-000 | S7: Leonardo Nunes de Castro | T7: Cristiane Aparecida Borges | U7: 44994 | W7: indicação amiga Livia | X7: valor social
A8: =IF(E8<>0, MONTH(E8),"") -> 4 | B8: =IF(F8="","", IF(F8<12,"Criança",IF(F8<18,"Adolescente",IF(F8<26,"Jovem",IF(F8<60,"Adulto", "Idoso"))))) -> Adulto | C8: Stella Leal Souza Furlanetto | D8: Terapia | E8: 32985 | F8: =IF(E8>0, DATEDIF(E8,TODAY(),"Y"),"") -> 35 | G8: 44651 | H8: =IF(U8>0,U8,TODAY()) -> 45028 | I8: =IF(G8>0, ROUNDDOWN((H8-G8)/365,0)& " Anos e "& ROUNDDOWN(((H8-G8)-ROUNDDOWN((H8-G8)/365,0)*365)/30,0)&" meses","") -> 1 Anos e 0 meses | J8: 62 991701318 | K8: controle de qualidade | L8: 62 984084481 | M8: Marido Henrique | N8: stellalealsouza@hotmail.com | O8: Av.T14, 535 - Ed. Borges Landeiro Athenas, ap 2802 | P8: Setor Bueno | Q8: Goiânia | R8: 74230-130 | S8: Benedito Felisbino de Souza | T8: Lucineide Leal Souza | U8: 45028 | W8: indicação Dayse
A9: =IF(E9<>0, MONTH(E9),"") | B9: Adulto | C9: Mariana Gonçalves de Menezes | D9: Seção Avulsa | F9: =IF(E9>0, DATEDIF(E9,TODAY(),"Y"),"") | G9: 44655 | H9: =IF(U9>0,U9,TODAY()) -> 44655 | I9: =IF(G9>0, ROUNDDOWN((H9-G9)/365,0)& " Anos e "& ROUNDDOWN(((H9-G9)-ROUNDDOWN((H9-G9)/365,0)*365)/30,0)&" meses","") -> 0 Anos e 0 meses | J9: 62 993003429 | K9: personal | L9: 62 993003566 | M9: esposa Isadora | N9: izadora.zootec@gmail.com | Q9: Goiânia | U9: 44655 | W9: doctoralia
A10: =IF(E10<>0, MONTH(E10),"") -> 9 | B10: =IF(F10="","", IF(F10<12,"Criança",IF(F10<18,"Adolescente",IF(F10<26,"Jovem",IF(F10<60,"Adulto", "Idoso"))))) -> Adulto | C10: Caio Andrade de Souza | D10: Terapia | E10: 33877 | F10: =IF(E10>0, DATEDIF(E10,TODAY(),"Y"),"") -> 33 | G10: 44658 | H10: =IF(U10>0,U10,TODAY()) -> 44972 | I10: =IF(G10>0, ROUNDDOWN((H10-G10)/365,0)& " Anos e "& ROUNDDOWN(((H10-G10)-ROUNDDOWN((H10-G10)/365,0)*365)/30,0)&" meses","") -> 0 Anos e 10 meses | J10: 62 981389186 | K10: engenheiro civil | L10: 62 983007799 | M10: irmão Lucas | N10: caio.souzaeng@outlook.com | O10: Rua T37, 2300 - Ed. DNA Smart Style Bloco G, ap 1401 | P10: Setor Bueno | Q10: Goiânia | R10: 74230-022 | U10: 44972 | V10: 9535323644 | W10: indicação de paciente - Mariane
A11: =IF(E11<>0, MONTH(E11),"") -> 3 | B11: =IF(F11="","", IF(F11<12,"Criança",IF(F11<18,"Adolescente",IF(F11<26,"Jovem",IF(F11<60,"Adulto", "Idoso"))))) -> Adulto | C11: Renata Ribeiro | D11: Terapia | E11: 32575 | F11: =IF(E11>0, DATEDIF(E11,TODAY(),"Y"),"") -> 36 | G11: 44667 | H11: =IF(U11>0,U11,TODAY()) -> 45490 | I11: =IF(G11>0, ROUNDDOWN((H11-G11)/365,0)& " Anos e "& ROUNDDOWN(((H11-G11)-ROUNDDOWN((H11-G11)/365,0)*365)/30,0)&" meses","") -> 2 Anos e 3 meses | J11: 62 999757543 | K11: contadora | L11: 62 984329324 | M11: mãe Veracine | N11: renata_rib@hotmail.co. | O11: Rua R17, 335 - Ed. Feel Home Lago das Rosas, ap 1504 | P11: Setor Oeste | Q11: Goiânia | R11: 74125-170 | S11: Elias Araújo Ribeiro + | T11: Veranice Machado Mesquita Ribeiro | U11: 45490 | V11: 3265415198 | W11: doctoralia
A12: =IF(E12<>0, MONTH(E12),"") | B12: Adulto | C12: Isaac Costa da Silva | D12: Seção Avulsa | F12: 30 | G12: 44707 | H12: =IF(U12>0,U12,TODAY()) -> 44707 | I12: =IF(G12>0, ROUNDDOWN((H12-G12)/365,0)& " Anos e "& ROUNDDOWN(((H12-G12)-ROUNDDOWN((H12-G12)/365,0)*365)/30,0)&" meses","") -> 0 Anos e 0 meses | J12: 62 991459990 | Q12: Goiânia | U12: 44707 | W12: doctoralia
A13: =IF(E13<>0, MONTH(E13),"") -> 11 | B13: =IF(F13="","", IF(F13<12,"Criança",IF(F13<18,"Adolescente",IF(F13<26,"Jovem",IF(F13<60,"Adulto", "Idoso"))))) -> Adulto | C13: Aurélio Rezende Lelis | D13: Terapia | E13: 28802 | F13: =IF(E13>0, DATEDIF(E13,TODAY(),"Y"),"") -> 47 | G13: 44707 | H13: =IF(U13>0,U13,TODAY()) -> 45042 | I13: =IF(G13>0, ROUNDDOWN((H13-G13)/365,0)& " Anos e "& ROUNDDOWN(((H13-G13)-ROUNDDOWN((H13-G13)/365,0)*365)/30,0)&" meses","") -> 0 Anos e 11 meses | J13: 62 985341313 | K13: empresário - farmácias | L13: 62 35111459 | M13: mãe Marilda | N13: aureliolelis@hotmail.com | O13: Rua Leopoldo de Bulhões, 1310 | P13: Centro | Q13: Inhumas/GO | R13: 75400-568 | U13: 45042 | W13: doctoralia
A14: =IF(E14<>0, MONTH(E14),"") -> 5 | B14: =IF(F14="","", IF(F14<12,"Criança",IF(F14<18,"Adolescente",IF(F14<26,"Jovem",IF(F14<60,"Adulto", "Idoso"))))) -> Criança | C14: Wallyson Guimarães Brito | D14: Seção Avulsa | E14: 42881 | F14: =IF(E14>0, DATEDIF(E14,TODAY(),"Y"),"") -> 8 | G14: 44711 | H14: =IF(U14>0,U14,TODAY()) -> 44711 | I14: =IF(G14>0, ROUNDDOWN((H14-G14)/365,0)& " Anos e "& ROUNDDOWN(((H14-G14)-ROUNDDOWN((H14-G14)/365,0)*365)/30,0)&" meses","") -> 0 Anos e 0 meses | L14: 62 982619515 | M14: mãe Thyara | N14: thyaraguimaraes05@gmail.com | O14: Rua Antônio Dumont Alves, Qd 66,Lt 23 Cs 2 | P14: Vila Maria | Q14: Aparecida de Goiânia/GO | R14: 74919-395 | S14: Uanderson Alves de Brito | T14: Thyara Guimarães Crispinho | U14: 44711 | W14: doctoralia
A15: =IF(E15<>0, MONTH(E15),"") | B15: =IF(F15="","", IF(F15<12,"Criança",IF(F15<18,"Adolescente",IF(F15<26,"Jovem",IF(F15<60,"Adulto", "Idoso"))))) -> Adulto | C15: Daniel Berg | D15: Seção Avulsa | F15: 28 | G15: 44713 | H15: =IF(U15>0,U15,TODAY()) -> 44713 | I15: =IF(G15>0, ROUNDDOWN((H15-G15)/365,0)& " Anos e "& ROUNDDOWN(((H15-G15)-ROUNDDOWN((H15-G15)/365,0)*365)/30,0)&" meses","") -> 0 Anos e 0 meses | J15: 62 984605723 | N15: bergdaniel309@gmail.com | Q15: Goiânia | U15: 44713 | W15: doctoralia
A16: =IF(E16<>0, MONTH(E16),"") | B16: Adulto | C16: Paulo Cezar Rodrigues Luz | D16: Seção Avulsa | G16: 44718 | H16: =IF(U16>0,U16,TODAY()) -> 44718 | I16: =IF(G16>0, ROUNDDOWN((H16-G16)/365,0)& " Anos e "& ROUNDDOWN(((H16-G16)-ROUNDDOWN((H16-G16)/365,0)*365)/30,0)&" meses","") -> 0 Anos e 0 meses | J16: 62 9820 5643 | N16: pcluz62@gmail.com | Q16: Goiânia | U16: 44718 | V16: 70264190130 | W16: doctoralia
A17: =IF(E17<>0, MONTH(E17),"") -> 5 | B17: =IF(F17="","", IF(F17<12,"Criança",IF(F17<18,"Adolescente",IF(F17<26,"Jovem",IF(F17<60,"Adulto", "Idoso"))))) -> Adulto | C17: Andre Junio Bons Olhos Fernandes | D17: Terapia | E17: 36293 | F17: =IF(E17>0, DATEDIF(E17,TODAY(),"Y"),"") -> 26 | G17: 44734 | H17: =IF(U17>0,U17,TODAY()) -> 44785 | I17: =IF(G17>0, ROUNDDOWN((H17-G17)/365,0)& " Anos e "& ROUNDDOWN(((H17-G17)-ROUNDDOWN((H17-G17)/365,0)*365)/30,0)&" meses","") -> 0 Anos e 1 meses | J17: 62993339167 | L17: 62 984447421 | M17: mãe Ana Flávia | N17: andrejunior1305@gmail.com | O17: Rua Aluísio Alvarenga Qd 36 Lt 20 | P17: Residencial Santa Fé | Q17: Goiânia | R17: 74356-285 | U17: 44785 | W17: doctoralia
A18: =IF(E18<>0, MONTH(E18),"") -> 11 | B18: =IF(F18="","", IF(F18<12,"Criança",IF(F18<18,"Adolescente",IF(F18<26,"Jovem",IF(F18<60,"Adulto", "Idoso"))))) -> Jovem | C18: José Wictor Rodrigues Moura | D18: Avaliação | E18: 36847 | F18: =IF(E18>0, DATEDIF(E18,TODAY(),"Y"),"") -> 25 | G18: 44763 | H18: =IF(U18>0,U18,TODAY()) -> 44966 | I18: =IF(G18>0, ROUNDDOWN((H18-G18)/365,0)& " Anos e "& ROUNDDOWN(((H18-G18)-ROUNDDOWN((H18-G18)/365,0)*365)/30,0)&" meses","") -> 0 Anos e 6 meses | J18: 62 991521595 | K18: desing gráfico | L18: 64 981327690 | M18: mãe | N18: wictorrodrigueslg@gmail.com | Q18: Goiânia | U18: 44966 | V18: 70333973135 | W18: doctoralia
A19: =IF(E19<>0, MONTH(E19),"") -> 9 | B19: =IF(F19="","", IF(F19<12,"Criança",IF(F19<18,"Adolescente",IF(F19<26,"Jovem",IF(F19<60,"Adulto", "Idoso"))))) -> Jovem | C19: Arthur Augusthus Ferreira Cabral | D19: Avaliação/Terapia | E19: 38233 | F19: =IF(E19>0, DATEDIF(E19,TODAY(),"Y"),"") -> 21 | G19: 44778 | H19: =IF(U19>0,U19,TODAY()) -> 45021 | I19: =IF(G19>0, ROUNDDOWN((H19-G19)/365,0)& " Anos e "& ROUNDDOWN(((H19-G19)-ROUNDDOWN((H19-G19)/365,0)*365)/30,0)&" meses","") -> 0 Anos e 8 meses | K19: estudante - medicina | L19: 62 981260166 | M19: mãe Renata | O19: Rua T.29, 484, Qd.41, Lt.08/09 - Ed. Excellence ap 1303 | P19: Setor Bueno | Q19: Goiânia | R19: 74210-050 | S19: Allyson Ribeiro e Silva Cabral | T19: Renata Claudia Santos Ferreira Cabral | U19: 45021 | V19: 03534079175 | W19: doctoralia
A20: =IF(E20<>0, MONTH(E20),"") -> 4 | B20: =IF(F20="","", IF(F20<12,"Criança",IF(F20<18,"Adolescente",IF(F20<26,"Jovem",IF(F20<60,"Adulto", "Idoso"))))) -> Adulto | C20: Jefferson Bevenuto dos Santos | D20: Terapia | E20: 33353 | F20: =IF(E20>0, DATEDIF(E20,TODAY(),"Y"),"") -> 34 | G20: 44790 | H20: =IF(U20>0,U20,TODAY()) -> 44912 | I20: =IF(G20>0, ROUNDDOWN((H20-G20)/365,0)& " Anos e "& ROUNDDOWN(((H20-G20)-ROUNDDOWN((H20-G20)/365,0)*365)/30,0)&" meses","") -> 0 Anos e 4 meses | J20: 62 999657858 | K20: cantor | L20: 62 981785672 | M20: empresário Thiago | Q20: Terezópolis/GO | U20: 44912 | W20: doctoralia
A21: =IF(E21<>0, MONTH(E21),"") -> 9 | B21: =IF(F21="","", IF(F21<12,"Criança",IF(F21<18,"Adolescente",IF(F21<26,"Jovem",IF(F21<60,"Adulto", "Idoso"))))) -> Adulto | C21: Bruno Machado de Aguiar | D21: Terapia | E21: 32393 | F21: =IF(E21>0, DATEDIF(E21,TODAY(),"Y"),"") -> 37 | G21: 44790 | H21: =IF(U21>0,U21,TODAY()) -> 44912 | I21: =IF(G21>0, ROUNDDOWN((H21-G21)/365,0)& " Anos e "& ROUNDDOWN(((H21-G21)-ROUNDDOWN((H21-G21)/365,0)*365)/30,0)&" meses","") -> 0 Anos e 4 meses | J21: 62 981785672 | K21: cantor | L21: 62 981785672 | M21: empresário Thiago | Q21: Terezópolis/GO | U21: 44912 | W21: doctoralia
A22: =IF(E22<>0, MONTH(E22),"") | B22: Adulto | C22: Gustavo Henrique Luz Resende | D22: Seção Avulsa | F22: 29 | G22: 44791 | H22: =IF(U22>0,U22,TODAY()) -> 44791 | I22: =IF(G22>0, ROUNDDOWN((H22-G22)/365,0)& " Anos e "& ROUNDDOWN(((H22-G22)-ROUNDDOWN((H22-G22)/365,0)*365)/30,0)&" meses","") -> 0 Anos e 0 meses | J22: 62 994245909 | U22: 44791 | W22: doctoralia
A23: =IF(E23<>0, MONTH(E23),"") -> 8 | B23: =IF(F23="","", IF(F23<12,"Criança",IF(F23<18,"Adolescente",IF(F23<26,"Jovem",IF(F23<60,"Adulto", "Idoso"))))) -> Adulto | C23: Jarbas Martins Jesuino Junior | D23: Terapia | E23: 32365 | F23: =IF(E23>0, DATEDIF(E23,TODAY(),"Y"),"") -> 37 | G23: 44797 | H23: =IF(U23>0,U23,TODAY()) -> 45261 | I23: =IF(G23>0, ROUNDDOWN((H23-G23)/365,0)& " Anos e "& ROUNDDOWN(((H23-G23)-ROUNDDOWN((H23-G23)/365,0)*365)/30,0)&" meses","") -> 1 Anos e 3 meses | J23: 62 996344824 | K23: engenheiro agronômo | L23: 16 993146855 | M23: pai | N23: jarbas.jesuino@corteva.com | O23: Rua Bento Peneago, 241 | P23: Centro | Q23: Jataí/GO | R23: 75800-055 | U23: 45261 | V23: 36907569876 | W23: indicação supervisora Juliana
A24: =IF(E24<>0, MONTH(E24),"") -> 3 | B24: =IF(F24="","", IF(F24<12,"Criança",IF(F24<18,"Adolescente",IF(F24<26,"Jovem",IF(F24<60,"Adulto", "Idoso"))))) -> Adulto | C24: Ivone Rodrigues de Castro | D24: Terapia | E24: 24924 | F24: =IF(E24>0, DATEDIF(E24,TODAY(),"Y"),"") -> 57 | G24: 44798 | H24: =IF(U24>0,U24,TODAY()) -> 44973 | I24: =IF(G24>0, ROUNDDOWN((H24-G24)/365,0)& " Anos e "& ROUNDDOWN(((H24-G24)-ROUNDDOWN((H24-G24)/365,0)*365)/30,0)&" meses","") -> 0 Anos e 5 meses | J24: 31 997261778 | K24: engenheiro civil | L24: 11 995165444 | M24: irmã Magda | N24: ivonecastro.gyn@gmail.com | O24: Avenida José Batista Gregório, acesso 03, casa 52 | P24: Conj Resid Terra Nova | Q24: Goiânia | R24: 74477-700 | U24: 44973 | W24: doctoralia
A25: =IF(E25<>0, MONTH(E25),"") -> 7 | B25: =IF(F25="","", IF(F25<12,"Criança",IF(F25<18,"Adolescente",IF(F25<26,"Jovem",IF(F25<60,"Adulto", "Idoso"))))) -> Adulto | C25: Matheus de Paula Carvalho | D25: Avaliação | E25: 35255 | F25: =IF(E25>0, DATEDIF(E25,TODAY(),"Y"),"") -> 29 | G25: 44812 | H25: =IF(U25>0,U25,TODAY()) -> 44896 | I25: =IF(G25>0, ROUNDDOWN((H25-G25)/365,0)& " Anos e "& ROUNDDOWN(((H25-G25)-ROUNDDOWN((H25-G25)/365,0)*365)/30,0)&" meses","") -> 0 Anos e 2 meses | J25: 62 985268791 | K25: empresário - produtos hospitalares | O25: Rua Joana Darc, Qd 24 Lt. 06 | P25: Centro | Q25: Santo Antônio de Goiás/GO | R25: 75375-000 | T25: Eliane Marques de Paula | U25: 44896 | V25: 04777044173 | W25: doctoralia
A26: =IF(E26<>0, MONTH(E26),"") -> 4 | B26: =IF(F26="","", IF(F26<12,"Criança",IF(F26<18,"Adolescente",IF(F26<26,"Jovem",IF(F26<60,"Adulto", "Idoso"))))) -> Adulto | C26: Diogo Alberto da Silva | D26: Avaliação | E26: 31870 | F26: =IF(E26>0, DATEDIF(E26,TODAY(),"Y"),"") -> 38 | G26: 44832 | H26: =IF(U26>0,U26,TODAY()) -> 44917 | I26: =IF(G26>0, ROUNDDOWN((H26-G26)/365,0)& " Anos e "& ROUNDDOWN(((H26-G26)-ROUNDDOWN((H26-G26)/365,0)*365)/30,0)&" meses","") -> 0 Anos e 2 meses | J26: 62 994622755 | K26: desing gráfico | L26: 62 981439141 | M26: esposa Lorena | Q26: Goiânia | U26: 44917 | V26: 02112768123 | W26: doctoralia
A27: =IF(E27<>0, MONTH(E27),"") -> 6 | B27: =IF(F27="","", IF(F27<12,"Criança",IF(F27<18,"Adolescente",IF(F27<26,"Jovem",IF(F27<60,"Adulto", "Idoso"))))) -> Criança | C27: Beatriz Bezerra Almeida | D27: Avaliação | E27: 42156 | F27: =IF(E27>0, DATEDIF(E27,TODAY(),"Y"),"") -> 10 | G27: 44853 | H27: =IF(U27>0,U27,TODAY()) -> 44951 | I27: =IF(G27>0, ROUNDDOWN((H27-G27)/365,0)& " Anos e "& ROUNDDOWN(((H27-G27)-ROUNDDOWN((H27-G27)/365,0)*365)/30,0)&" meses","") -> 0 Anos e 3 meses | K27: estudante | L27: 62 981449193 / 62 981236788 | M27: pai / mãe | Q27: Goiânia | S27: Fagner A. Morais de Almeida | T27: Marlise de Sousa Bezerra | U27: 44951 | V27: 07740251151 | W27: doctoralia
